Workbook
Name Slicer_company_size: #N/A
Name Slicer_experience_level: #N/A
Name Slicer_region: #N/A
Name Slicer_remote_category: #N/A

Sheet Salary_Calculator
A1: Experience Level: | B1: EN
A2: Company Size: | B2: M
A3: Remote Work: | B3: 100
A4: Region: | B4: North America
A6: Estimated Salary: | B6: =AVERAGEIFS(DS_Salaries!$G:G, DS_Salaries!$B:$B, B1,DS_Salaries!$K:$K, B2, DS_Salaries!$O:$O, B4) -> 75600

Sheet Salary_Bands
A1: Salary Bands | B1: Count
A2: <$50k | B2: =B4 -> 155
A3: $50k-$100k | B3: =COUNTIFS(DS_Salaries!G:G, ">=50000", DS_Salaries!G:G, "<=100000") -> 188
A4: $100k-$150k | B4: =COUNTIFS(DS_Salaries!G:G, ">=100000", DS_Salaries!G:G, "<=150000") -> 155

Sheet PT_Experience
A1: Average Salary by Experience Level
A3: Row Labels | B3: Average of salary_in_usd | C3: Count of salary_in_usd
A4: EN | B4: 62305.885 | C4: 87
A5: EX | B5: 199392.04 | C5: 26
A6: MI | B6: 88612.058 | C6: 206
A7: SE | B7: 138374.88 | C7: 243
A8: Grand Total | B8: 111181.47 | C8: 562

Sheet PT_CompanySize
A1: Salary by Company Size
A3: Row Labels | B3: Average of salary_in_usd | C3: Count of salary_in_usd | D3: Sum of salary_in_usd
A4: L | B4: 118213.88 | C4: 193 | D4: 22815279
A5: M | B5: 115576.57 | C5: 288 | D5: 33286053
A6: S | B6: 78798.185 | C6: 81 | D6: 6382653
A7: Grand Total | B7: 111181.47 | C7: 562 | D7: 62483985

Sheet PT_Region
A1: Salary by Region
A3: Row Labels | B3: Average of salary_in_usd | C3: Count of salary_in_usd
A4: Asia | B4: 45495.973 | C4: 37
A5: Europe | B5: 70329.511 | C5: 141
A6: North America | B6: 140178.43 | C6: 348
A7: Oceania | B7: 112282 | C7: 4
A8: Other | B8: 56861.481 | C8: 27
A9: South America | B9: 23538 | C9: 5
A10: (blank)
A11: Grand Total | B11: 111181.47 | C11: 562

Sheet PT_Remote
A1: Salary by Remote Category
A3: Row Labels | B3: Average of salary_in_usd | C3: Count of salary_in_usd
A4: Fully Remote | B4: 121101.63 | C4: 345
A5: Hybrid | B5: 80721.898 | C5: 98
A6: On-site | B6: 107505.67 | C6: 119
A7: Grand Total | B7: 111181.47 | C7: 562

Sheet Dashboard
G1: COMPENSATION ANALYTICS DASHBOARD
I2: KPI
I3: Total Records | K3: =Summary_Stats!C4 -> 562
I4: Average Salary | K4: =Summary_Stats!C5 -> 111181.47
I5: Median Salary | K5: =Summary_Stats!C6 -> 100000
I6: Max Salary | K6: =Summary_Stats!C8 -> 600000
I7: Salary Range | K7: =Summary_Stats!C8 - Summary_Stats!C7 -> 594591

Sheet PT_CrossTab
A1: Cross-Tabulation (Experience × Company Size)
A3: Average of salary_in_usd | B3: Column Labels
A4: Row Labels | B4: L | C4: M | D4: S | E4: Grand Total
A5: EN | B5: 72813.241 | C5: 51919.103 | D5: 62185.31 | E5: 62305.885
A6: EX | B6: 221942.18 | C6: 178241.75 | D6: 201309.33 | E6: 199392.04
A7: MI | B7: 96903.31 | C7: 91488.874 | D7: 52694.926 | E7: 88612.058
A8: SE | B8: 146702.22 | C8: 137829.31 | D8: 116026.73 | E8: 138374.88
A9: Grand Total | B9: 118213.88 | C9: 115576.57 | D9: 78798.185 | E9: 111181.47

Sheet PT_SalaryTrends
A3: Row Labels | B3: Average of salary_in_usd
A4: 2020 | B4: 95813
A5: 2021 | B5: 100786.23
A6: 2022 | B6: 123089.1
A7: Grand Total | B7: 111181.47

Sheet DS_Salaries
A1: work_year | B1: experience_level | C1: employment_type | D1: job_title | E1: salary | F1: salary_currency | G1: salary_in_usd | H1: employee_residence | I1: remote_ratio | J1: company_location | K1: company_size | L1: experience_level_numeric | M1: company_size_numeric | N1: remote_category | O1: region | P1: salary_band
A2: 2020 | B2: MI | C2: FT | D2: Data Scientist | E2: 70000 | F2: EUR | G2: 79833 | H2: DE | I2: 0 | J2: DE | K2: L | L2: 2 | M2: 3 | N2: On-site | O2: Europe | P2: Mid (50k-100k)
A3: 2020 | B3: SE | C3: FT | D3: Machine Learning Scientist | E3: 260000 | F3: USD | G3: 260000 | H3: JP | I3: 0 | J3: JP | K3: S | L3: 3 | M3: 1 | N3: On-site | O3: Asia | P3: Executive (>150k)
A4: 2020 | B4: SE | C4: FT | D4: Big Data Engineer | E4: 85000 | F4: GBP | G4: 109024 | H4: GB | I4: 50 | J4: GB | K4: M | L4: 3 | M4: 2 | N4: Hybrid | O4: Europe | P4: Senior (100k-150k)
A5: 2020 | B5: MI | C5: FT | D5: Product Data Analyst | E5: 20000 | F5: USD | G5: 20000 | H5: HN | I5: 0 | J5: HN | K5: S | L5: 2 | M5: 1 | N5: On-site | O5: Other | P5: Entry (<50k)
A6: 2020 | B6: SE | C6: FT | D6: Machine Learning Engineer | E6: 150000 | F6: USD | G6: 150000 | H6: US | I6: 50 | J6: US | K6: L | L6: 3 | M6: 3 | N6: Hybrid | O6: North America | P6: Executive (>150k)
A7: 2020 | B7: EN | C7: FT | D7: Data Analyst | E7: 72000 | F7: USD | G7: 72000 | H7: US | I7: 100 | J7: US | K7: L | L7: 1 | M7: 3 | N7: Fully Remote | O7: North America | P7: Mid (50k-100k)
A8: 2020 | B8: SE | C8: FT | D8: Lead Data Scientist | E8: 190000 | F8: USD | G8: 190000 | H8: US | I8: 100 | J8: US | K8: S | L8: 3 | M8: 1 | N8: Fully Remote | O8: North America | P8: Executive (>150k)
A9: 2020 | B9: MI | C9: FT | D9: Data Scientist | E9: 11000000 | F9: HUF | G9: 35735 | H9: HU | I9: 50 | J9: HU | K9: L | L9: 2 | M9: 3 | N9: Hybrid | O9: Other | P9: Entry (<50k)
A10: 2020 | B10: MI | C10: FT | D10: Business Data Analyst | E10: 135000 | F10: USD | G10: 135000 | H10: US | I10: 100 | J10: US | K10: L | L10: 2 | M10: 3 | N10: Fully Remote | O10: North America | P10: Senior (100k-150k)
A11: 2020 | B11: SE | C11: FT | D11: Lead Data Engineer | E11: 125000 | F11: USD | G11: 125000 | H11: NZ | I11: 50 | J11: NZ | K11: S | L11: 3 | M11: 1 | N11: Hybrid | O11: Oceania | P11: Senior (100k-150k)
A12: 2020 | B12: EN | C12: FT | D12: Data Scientist | E12: 45000 | F12: EUR | G12: 51321 | H12: FR | I12: 0 | J12: FR | K12: S | L12: 1 | M12: 1 | N12: On-site | O12: Europe | P12: Mid (50k-100k)
A13: 2020 | B13: MI | C13: FT | D13: Data Scientist | E13: 3000000 | F13: INR | G13: 40481 | H13: IN | I13: 0 | J13: IN | K13: L | L13: 2 | M13: 3 | N13: On-site | O13: Asia | P13: Entry (<50k)
... A563: 2022 | B563: MI | C563: FT | D563: AI Scientist | E563: 200000 | F563: USD | G563: 200000 | H563: IN | I563: 100 | J563: US | K563: L | L563: 2 | M563: 3 | N563: Fully Remote | O563: North America | P563: Executive (>150k)

Sheet SO_Survey
A1: ResponseId | B1: MainBranch | C1: Age | D1: EdLevel | E1: Employment | F1: EmploymentAddl | G1: WorkExp | H1: LearnCodeChoose | I1: LearnCode | J1: LearnCodeAI | K1: AILearnHow | L1: YearsCode | M1: DevType | N1: OrgSize | O1: ICorPM | P1: RemoteWork | Q1: PurchaseInfluence | R1: TechEndorseIntro | S1: TechEndorse_1 | T1: TechEndorse_2 | U1: TechEndorse_3 | V1: TechEndorse_4 | W1: TechEndorse_5 | X1: TechEndorse_6 | Y1: TechEndorse_7 | Z1: TechEndorse_8 | AA1: TechEndorse_9 | AB1: TechEndorse_13 | AC1: TechEndorse_13_TEXT | AD1: TechOppose_1 | AE1: TechOppose_2 | AF1: TechOppose_3 | AG1: TechOppose_5 | AH1: TechOppose_7 | AI1: TechOppose_9 | AJ1: TechOppose_11 | AK1: TechOppose_13 | AL1: TechOppose_16 | AM1: TechOppose_15 | AN1: TechOppose_15_TEXT | AO1: Industry | AP1: JobSatPoints_1 | AQ1: JobSatPoints_2 | AR1: JobSatPoints_3 | AS1: JobSatPoints_4 | AT1: JobSatPoints_5 | AU1: JobSatPoints_6 | AV1: JobSatPoints_7 | AW1: JobSatPoints_8 | AX1: JobSatPoints_9 | AY1: JobSatPoints_10 | AZ1: JobSatPoints_11 | BA1: JobSatPoints_13 | BB1: JobSatPoints_14 | BC1: JobSatPoints_15 | BD1: JobSatPoints_16 | BE1: JobSatPoints_15_TEXT | BF1: AIThreat | BG1: NewRole | BH1: ToolCountWork | BI1: ToolCountPersonal | BJ1: Country | BK1: Currency | BL1: CompTotal | BM1: LanguageChoice | BN1: LanguageHaveWorkedWith | BO1: LanguageWantToWorkWith | BP1: LanguageAdmired | BQ1: LanguagesHaveEntry | BR1: LanguagesWantEntry | BS1: DatabaseChoice | BT1: DatabaseHaveWorkedWith | BU1: DatabaseWantToWorkWith | BV1: DatabaseAdmired | BW1: DatabaseHaveEntry | BX1: DatabaseWantEntry | BY1: PlatformChoice | BZ1: PlatformHaveWorkedWith | CA1: PlatformWantToWorkWith | CB1: PlatformAdmired | CC1: PlatformHaveEntry | CD1: PlatformWantEntry | CE1: WebframeChoice | CF1: WebframeHaveWorkedWith | CG1: WebframeWantToWorkWith | CH1: WebframeAdmired | CI1: WebframeHaveEntry | CJ1: WebframeWantEntry | CK1: DevEnvsChoice | CL1: DevEnvsHaveWorkedWith | CM1: DevEnvsWantToWorkWith | CN1: DevEnvsAdmired | CO1: DevEnvHaveEntry | CP1: DevEnvWantEntry | CQ1: SOTagsHaveWorkedWith | CR1: SOTagsWantToWorkWith | CS1: SOTagsAdmired | CT1: SOTagsHaveEntry | CU1: SOTagsWant Entry | CV1: OpSysPersonal use | CW1: OpSysProfessional use | CX1: OfficeStackAsyncHaveWorkedWith | CY1: OfficeStackAsyncWantToWorkWith | CZ1: OfficeStackAsyncAdmired | DA1: OfficeStackHaveEntry | DB1: OfficeStackWantEntry | DC1: CommPlatformHaveWorkedWith | DD1: CommPlatformWantToWorkWith | DE1: CommPlatformAdmired | DF1: CommPlatformHaveEntr | DG1: CommPlatformWantEntr | DH1: AIModelsChoice | DI1: AIModelsHaveWorkedWith | DJ1: AIModelsWantToWorkWith | DK1: AIModelsAdmired | DL1: AIModelsHaveEntry | DM1: AIModelsWantEntry | DN1: SOAccount | DO1: SOVisitFreq | DP1: SODuration | DQ1: SOPartFreq | DR1: SO_Dev_Content | DS1: SO_Actions_1 | DT1: SO_Actions_16 | DU1: SO_Actions_3 | DV1: SO_Actions_4 | DW1: SO_Actions_5 | DX1: SO_Actions_6 | DY1: SO_Actions_9 | DZ1: SO_Actions_7 | EA1: SO_Actions_10 | EB1: SO_Actions_15 | EC1: SO_Actions_15_TEXT | ED1: SOComm | EE1: SOFriction | EF1: AISelect | EG1: AISent | EH1: AIAcc | EI1: AIComplex | EJ1: AIToolCurrently partially AI | EK1: AIToolDon't plan to use AI for this task | EL1: AIToolPlan to partially use AI | EM1: AIToolPlan to mostly use AI | EN1: AIToolCurrently mostly AI | EO1: AIFrustration | EP1: AIExplain | EQ1: AIAgents | ER1: AIAgentChange | ES1: AIAgent_Uses | ET1: AgentUsesGeneral | EU1: AIAgentImpactSomewhat agree | EV1: AIAgentImpactNeutral | EW1: AIAgentImpactSomewhat disagree | EX1: AIAgentImpactStrongly agree | EY1: AIAgentImpactStrongly disagree | EZ1: AIAgentChallengesNeutral | FA1: AIAgentChallengesSomewhat disagree | FB1: AIAgentChallengesStrongly agree | FC1: AIAgentChallengesSomewhat agree | FD1: AIAgentChallengesStrongly disagree | FE1: AIAgentKnowledge | FF1: AIAgentKnowWrite | FG1: AIAgentOrchestration | FH1: AIAgentOrchWrite | FI1: AIAgentObserveSecure | FJ1: AIAgentObsWrite | FK1: AIAgentExternal | FL1: AIAgentExtWrite | FM1: AIHuman | FN1: AIOpen | FO1: ConvertedCompYearly | FP1: JobSat
A2: 9 | B2: I am a developer by profession | C2: 25-34 years old | D2: Bachelor’s degree (B.A., B.S., B.Eng., etc.) | E2: Employed | F2: Caring for dependents (children, elderly, etc.);Volunteering (regularly) | G2: 9 | H2: Yes, I am not new to coding but am learning new coding techniques or programming language | I2: Online Courses or Certification (includes all media types);Other online resources (e.g. standard search, forum, online community);Books / Physical media;Videos (not associated with specific online course or certification);Stack Overflow or Stack Exchange;Technical documentation (is generated for/by the tool or system);AI CodeGen tools or AI-enabled apps;Blogs or podcasts | J2: Yes, I learned how to use AI-enabled tools for my personal curiosity and/or hobbies | K2: Technical documentation (is generated for/by the tool or system);Videos (not associated with specific online course or certification);Other online resources (e.g. standard search, forum, online community);Blogs or podcasts | L2: 15 | M2: Data engineer | N2: 5,000 to 9,999 employees | O2: Individual contributor | P2: Remote | Q2: Yes, I influenced the purchase of a tool that more than five colleagues use but it is not a substantial addition to the tech stack | R2: Personal Project | S2: 5 | T2: 7 | U2: 13 | V2: 4 | W2: 9 | X2: 8 | Y2: 12 | Z2: 2 | AA2: 11 | AB2: 14 | AD2: 11 | AE2: 13 | AF2: 10 | AG2: 1 | AH2: 5 | AI2: 9 | AJ2: 7 | AK2: 8 | AL2: 2 | AM2: 15 | AO2: Banking/Financial Services | AP2: 1 | AQ2: 2 | AR2: 4 | AS2: 5 | AT2: 6 | AU2: 7 | AV2: 8 | AW2: 9 | AX2: 10 | AY2: 11 | AZ2: 12 | BA2: 13 | BB2: 14 | BC2: 15 | BD2: 3 | BF2: No | BG2: I have transitioned into a new career and/or industry voluntarily | BJ2: Ukraine | BK2: USD United States dollar | BL2: 70000 | BN2: Java;Python;Scala | BO2: Scala | BP2: Scala | BT2: Cassandra;Databricks SQL;DuckDB;Dynamodb;MariaDB;Microsoft SQL Server;MySQL;PostgreSQL;Snowflake;Amazon Redshift | BU2: Dynamodb;MySQL;PostgreSQL | BV2: Dynamodb;MySQL;PostgreSQL | BZ2: Amazon Web Services (AWS);Datadog;Docker;Microsoft Azure;Splunk | CA2: Amazon Web Services (AWS);Datadog;Microsoft Azure | CB2: Amazon Web Services (AWS);Datadog;Microsoft Azure | CF2: FastAPI;Spring Boot | CL2: IntelliJ IDEA;Notepad++;PyCharm;Visual Studio Code | DS2: 1 | DU2: 4 | DV2: 5 | DW2: 6 | DX2: 7 | DY2: 8 | DZ2: 9 | EA2: 11 | EB2: 15 | EF2: Yes, I use AI tools monthly or infrequently | EG2: Indifferent | EH2: Neither trust nor distrust | EI2: Neither good or bad at handling complex tasks | ES2: Software engineering;Data and analytics | FO2: 70000 | FP2: 8
A3: 17 | B3: I am not primarily a developer, but I write code sometimes as part of my work/studies | C3: 65 years or older | D3: Some college/university study without earning a degree | E3: Retired | F3: None of the above | G3: 20 | H3: No, I am not new to coding and did not learn new coding techniques or programming languages | J3: No, I didn't spend time learning in the past year | L3: 40 | M3: Financial analyst or engineer | R3: Personal Project | S3: 7 | T3: 12 | U3: 2 | V3: 11 | W3: 5 | X3: 10 | Y3: 6 | Z3: 9 | AA3: 3 | AB3: 14 | AC3: usefullness | AD3: 4 | AE3: 10 | AF3: 5 | AG3: 1 | AH3: 12 | AI3: 13 | AJ3: 3 | AK3: 2 | AL3: 11 | AM3: 15 | BI3: 1 | BJ3: Australia | BK3: AUD Australian dollar | BL3: 25000 | BM3: Yes | BQ3: MQL4 | BR3: MQL5 | BS3: No | BY3: No | CE3: No | CK3: No | CT3: None of these | CU3: Not listed | CV3: Windows | CW3: Windows | DA3: No | DB3: No | DH3: No | DN3: No | DO3: Less than once per month or monthly | DP3: I don't use Stack Overflow | DQ3: I have never participated in Q&A on Stack Overflow | DR3: Other (write in): | DS3: 11 | DU3: 5 | DV3: 2 | DW3: 7 | DX3: 8 | DY3: 4 | DZ3: 3 | EA3: 6 | EB3: 15 | EC3: I don't use stsck overflow | ED3: No, not at all | EE3: I don't use AI or AI-enabled tools | EF3: No, and I don't plan to | EG3: Very unfavorable | EH3: Highly distrust | EI3: I don't use AI tools for complex tasks / I don't know | EK3: Learning about a codebase;Project planning;Writing code;Documenting code;Debugging or fixing code;Testing code;Committing and reviewing code;Deployment and monitoring;Predictive analytics;Search for answers;Generating content or synthetic data;Creating or maintaining documentation;Learning new concepts or technologies;Other (write in): | EO3: I don’t use AI tools regularly | EP3: No | EQ3: No, and I don't plan to | ER3: No, but my development work has significantly changed due to non-AI factors | FB3: I am concerned about the accuracy of the information provided by AI agents.;Integrating AI agents with my existing tools and workflows can be difficult.;It takes significant time and effort to learn how to use AI agents effectively.;The cost of using certain AI agent platforms is a barrier.;I have concerns about the security and privacy of data when using AI agents.;My company's IT and/or InfoSec teams have strict rules that do not allow me to use AI agent tools or platforms | FM3: Other (please specify): | FN3: All the ones that INTELLIGENT programmers currently use | FO3: 16252
A4: 34 | B4: I am a developer by profession | C4: 45-54 years old | D4: Bachelor’s degree (B.A., B.S., B.Eng., etc.) | E4: Employed | F4: None of the above | G4: 24 | H4: Yes, I am not new to coding but am learning new coding techniques or programming language | I4: Stack Overflow or Stack Exchange;Technical documentation (is generated for/by the tool or system);AI CodeGen tools or AI-enabled apps | J4: No, I didn't spend time learning in the past year | L4: 26 | M4: Data engineer | N4: 5,000 to 9,999 employees | O4: Individual contributor | P4: Hybrid (some remote, leans heavy to in-person) | Q4: Yes, I influenced the purchase of a substantial addition to the tech stack | R4: Work | S4: 10 | T4: 5 | U4: 4 | V4: 7 | W4: 2 | X4: 11 | Y4: 8 | Z4: 3 | AA4: 1 | AB4: 14 | AD4: 12 | AE4: 2 | AF4: 5 | AG4: 1 | AH4: 9 | AI4: 8 | AJ4: 3 | AK4: 4 | AL4: 14 | AM4: 15 | AO4: Software Development | AP4: 3 | AQ4: 4 | AR4: 11 | AS4: 14 | AT4: 13 | AU4: 8 | AV4: 12 | AW4: 1 | AX4: 6 | AY4: 7 | AZ4: 2 | BA4: 9 | BB4: 10 | BC4: 15 | BD4: 5 | BF4: No | BG4: I have neither consider or transitioned into a new career or industry | BH4: 3 | BI4: 0 | BJ4: United States of America | BK4: USD United States dollar | BL4: 175000 | BM4: Yes | BN4: C#;Python;SQL | BS4: Yes | BT4: Microsoft SQL Server | BY4: Yes | BZ4: Amazon Web Services (AWS);Microsoft Azure;Terraform | CE4: Yes | CF4: ASP.NET;ASP.NET Core | CK4: Yes | CL4: Visual Studio;Visual Studio Code | CQ4: Amazon Bedrock | CV4: Windows | CW4: Windows;Windows Subsystem for Linux (WSL);Linux (non-WSL) | CX4: Azure Devops;Jira | DC4: Stack Overflow;Stack Exchange | DH4: No | DN4: Yes | DO4: A few times per week | DP4: Between 10 and 15 years | DQ4: A few times per month or weekly | DS4: 6 | DU4: 8 | DV4: 12 | DW4: 7 | DX4: 4 | DY4: 5 | DZ4: 2 | EA4: 10 | EB4: 15 | ED4: Yes, somewhat | EE4: Rarely, almost never | EF4: No, and I don't plan to | EG4: Indifferent | EH4: Neither trust nor distrust | EI4: Bad at handling complex tasks | EK4: Learning about a codebase;Project planning;Writing code;Documenting code;Debugging or fixing code;Testing code;Committing and reviewing code;Deployment and monitoring;Predictive analytics;Search for answers;Generating content or synthetic data;Creating or maintaining documentation;Learning new concepts or technologies;Other (write in): | EO4: I don’t use AI tools regularly | EP4: no | EQ4: No, and I don't plan to | ER4: Not at all or minimally | EZ4: I am concerned about the accuracy of the information provided by AI agents.;Integrating AI agents with my existing tools and workflows can be difficult.;It takes significant time and effort to learn how to use AI agents effectively.;The cost of using certain AI agent platforms is a barrier.;I have concerns about the security and privacy of data when using AI agents.;My company's IT and/or InfoSec teams have strict rules that do not allow me to use AI agent tools or platforms;Write in the most significant challenge if not listed above: | FN4: business logic | FO4: 175000 | FP4: 8
A5: 46 | B5: I am a developer by profession | C5: 45-54 years old | D5: Professional degree (JD, MD, Ph.D, Ed.D, etc.) | E5: Employed | F5: None of the above | G5: 20 | H5: No, I am not new to coding and did not learn new coding techniques or programming languages | J5: No, I learned something that was not related to AI or AI enablement as required for my job or to benefit my career | L5: 23 | M5: AI/ML engineer | N5: 20 to 99 employees | O5: Individual contributor | P5: Hybrid (some in-person, leans heavy to flexibility) | Q5: No | R5: Work | S5: 11 | T5: 2 | U5: 6 | V5: 10 | W5: 7 | X5: 3 | Y5: 12 | Z5: 5 | AA5: 4 | AB5: 14 | AD5: 13 | AE5: 3 | AF5: 6 | AG5: 5 | AH5: 1 | AI5: 4 | AJ5: 9 | AK5: 2 | AL5: 14 | AM5: 15 | AO5: Software Development | AP5: 5 | AQ5: 1 | AR5: 10 | AS5: 14 | AT5: 12 | AU5: 3 | AV5: 4 | AW5: 11 | AX5: 2 | AY5: 6 | AZ5: 7 | BA5: 13 | BB5: 9 | BC5: 15 | BD5: 8 | BF5: No | BG5: I have neither consider or transitioned into a new career or industry | BJ5: Hungary | BK5: HUF Hungarian forint | BL5: 28000000 | BM5: Yes | BN5: Java;MATLAB;OCaml;Python;Scala | BO5: OCaml;Python;Scala | BP5: OCaml;Python;Scala | BS5: Yes | BT5: PostgreSQL;SQLite | BU5: PostgreSQL;SQLite | BV5: PostgreSQL;SQLite | BY5: Yes | BZ5: Docker;Maven (build tool) | CA5: Docker;Poetry | CB5: Docker | CE5: Yes | CF5: FastAPI | CG5: FastAPI | CH5: FastAPI | CK5: Yes | CL5: IntelliJ IDEA;Jupyter Notebook/JupyterLab;Nano;PyCharm;Visual Studio Code | CM5: IntelliJ IDEA;Jupyter Notebook/JupyterLab;Nano;PyCharm;Visual Studio Code | CN5: IntelliJ IDEA;Jupyter Notebook/JupyterLab;Nano;PyCharm;Visual Studio Code | CQ5: Polars | CR5: Polars | CS5: Polars | CV5: Ubuntu | CW5: Ubuntu | CX5: GitHub;GitLab | CY5: GitHub;GitLab | CZ5: GitHub;GitLab | DC5: Stack Overflow;GitHub (public projects, not private repos);Slack (public channels, not work);YouTube;LinkedIn | DD5: Stack Overflow;GitHub (public projects, not private repos);Slack (public channels, not work);YouTube;LinkedIn | DE5: Stack Overflow;GitHub (public projects, not private repos);Slack (public channels, not work);YouTube;LinkedIn | DH5: No | DN5: Yes | DO5: Daily or almost daily | DP5: Between 10 and 15 years | DQ5: Infrequently, less than once per year | DR5: Job board | DS5: 1 | DU5: 2 | DV5: 8 | DW5: 13 | DX5: 9 | DY5: 14 | DZ5: 7 | EA5: 11 | EB5: 15 | ED5: Neutral | EE5: I don't use AI or AI-enabled tools | EF5: No, and I don't plan to | EG5: Very unfavorable | EH5: Highly distrust | EI5: Bad at handling complex tasks | EJ5: Learning about a codebase | EK5: Project planning;Writing code;Debugging or fixing code;Committing and reviewing code;Deployment and monitoring;Predictive analytics | EL5: Testing code;Generating content or synthetic data;Learning new concepts or technologies | EM5: Documenting code;Search for answers;Creating or maintaining documentation | EO5: AI solutions that are almost right, but not quite;Debugging AI-generated code is more time-consuming;I don’t use AI tools regularly | EP5: No. | EQ5: No, and I don't plan to | ER5: Not at all or minimally | EZ5: Integrating AI agents with my existing tools and workflows can be difficult.;The cost of using certain AI agent platforms is a barrier.;My company's IT and/or InfoSec teams have strict rules that do not allow me to use AI agent tools or platforms | FB5: I have concerns about the security and privacy of data when using AI agents. | FC5: I am concerned about the accuracy of the information provided by AI agents.;It takes significant time and effort to learn how to use AI agents effectively. | FM5: When I want to fully understand something;When I want to learn best practices | FO5: 80966 | FP5: 8
A6: 69 | B6: I am not primarily a developer, but I write code sometimes as part of my work/studies | C6: 45-54 years old | D6: Bachelor’s degree (B.A., B.S., B.Eng., etc.) | E6: Independent contractor, freelancer, or self-employed | F6: Caring for dependents (children, elderly, etc.);Engaged in paid work (20-29 hours per week) | G6: 31 | H6: Yes, I am not new to coding but am learning new coding techniques or programming language | I6: Online Courses or Certification (includes all media types);Other online resources (e.g. standard search, forum, online community);Books / Physical media;Videos (not associated with specific online course or certification);Technical documentation (is generated for/by the tool or system);School (i.e., University, College, etc) | J6: Yes, I learned how to use AI-enabled tools for my personal curiosity and/or hobbies | K6: Videos (not associated with specific online course or certification);Stack Overflow or Stack Exchange | L6: 20 | M6: Data engineer | N6: Just me - I am a freelancer, sole proprietor, etc. | O6: Individual contributor | P6: Hybrid (some remote, leans heavy to in-person) | Q6: Yes, I influenced the purchase of a tool that more than five colleagues use but it is not a substantial addition to the tech stack | R6: Work | AO6: Computer Systems Design and Services | BF6: No | BG6: I have strongly considered changing my career and/or the industry I work in | BH6: 15 | BI6: 15 | BJ6: France | BK6: EUR European Euro | BL6: 150000 | BM6: Yes | BN6: JavaScript;Python;R;SQL;TypeScript;VBA | BS6: Yes | BT6: MariaDB;Microsoft SQL Server;MySQL | BY6: Yes | BZ6: Docker;Kubernetes;Microsoft Azure;Podman;Terraform | CE6: No | CK6: Yes | CL6: Eclipse;Notepad++;Sublime Text;Visual Studio Code | CV6: Windows;Ubuntu;Windows Subsystem for Linux (WSL);Linux (non-WSL) | CW6: Windows | CX6: Azure Devops;Confluence;GitHub;Google Workspace;Jira | DC6: Stack Overflow;Discord;GitHub (public projects, not private repos);Slack (public channels, not work);YouTube;LinkedIn | DH6: No | DN6: Yes | DO6: A few times per month or weekly | DP6: Between 1 and 3 years | DQ6: I have never participated in Q&A on Stack Overflow | ED6: Yes, somewhat | EF6: Yes, I use AI tools monthly or infrequently | EG6: Indifferent | EH6: Somewhat trust | EI6: Bad at handling complex tasks | EK6: Project planning;Committing and reviewing code;Creating or maintaining documentation;Learning new concepts or technologies;Other (write in): | EL6: Learning about a codebase;Writing code;Documenting code;Debugging or fixing code;Testing code;Deployment and monitoring;Predictive analytics;Search for answers;Generating content or synthetic data | EO6: I don’t use AI tools regularly | EQ6: No, but I plan to | ER6: Not at all or minimally | EZ6: My company's IT and/or InfoSec teams have strict rules that do not allow me to use AI agent tools or platforms | FB6: It takes significant time and effort to learn how to use AI agents effectively.;The cost of using certain AI agent platforms is a barrier.;I have concerns about the security and privacy of data when using AI agents. | FC6: I am concerned about the accuracy of the information provided by AI agents.;Integrating AI agents with my existing tools and workflows can be difficult. | FM6: When I’m stuck and can’t explain the problem | FN6: Integration | FO6: 174022
A7: 86 | B7: I am a developer by profession | C7: 35-44 years old | D7: Master’s degree (M.A., M.S., M.Eng., MBA, etc.) | E7: Employed | F7: None of the above | G7: 15 | H7: Yes, I am not new to coding but am learning new coding techniques or programming language | I7: Other online resources (e.g. standard search, forum, online community);Stack Overflow or Stack Exchange;Technical documentation (is generated for/by the tool or system);Games or coding challenges | J7: Yes, I learned how to use AI-enabled tools for my personal curiosity and/or hobbies | K7: Videos (not associated with specific online course or certification);Other online resources (e.g. standard search, forum, online community);Colleague or on-the-job training;Stack Overflow or Stack Exchange | L7: 20 | M7: Developer, AI apps or physical AI | N7: 5,000 to 9,999 employees | O7: Individual contributor | P7: Remote | Q7: Yes, I influenced the purchase of a substantial addition to the tech stack | R7: Work | S7: 7 | T7: 1 | U7: 4 | V7: 11 | W7: 3 | X7: 2 | Y7: 9 | Z7: 5 | AA7: 6 | AB7: 13 | AD7: 10 | AE7: 3 | AF7: 2 | AG7: 5 | AH7: 4 | AI7: 7 | AJ7: 8 | AK7: 1 | AL7: 14 | AM7: 15 | AO7: Software Development | AP7: 4 | AQ7: 3 | AR7: 8 | AS7: 11 | AT7: 12 | AU7: 6 | AV7: 7 | AW7: 13 | AX7: 10 | AY7: 9 | AZ7: 1 | BA7: 14 | BB7: 5 | BC7: 15 | BD7: 2 | BF7: No | BG7: I have neither consider or transitioned into a new career or industry | BH7: 3 | BI7: 4 | BJ7: Italy | BK7: EUR European Euro | BL7: 120000 | BM7: Yes | BN7: C;C++;Python;Rust | BO7: Go | BQ7: CUDA | BR7: warp | BS7: No | BY7: Yes | BZ7: Amazon Web Services (AWS);Poetry | CA7: Amazon Web Services (AWS) | CB7: Amazon Web Services (AWS) | CE7: No | CK7: Yes | CL7: Claude Code;Vim;Visual Studio Code | CM7: Visual Studio Code | CN7: Visual Studio Code | CQ7: c++23 | CV7: Windows;MacOS;Ubuntu | CW7: Ubuntu | CX7: Confluence;GitHub;GitLab;Google Colab | CY7: GitHub;GitLab | CZ7: GitHub;GitLab | DC7: Stack Overflow;Discord | DD7: Stack Overflow | DE7: Stack Overflow | DH7: Yes | DI7: DeepSeek (R- Reasoning models);openAI Reasoning models;X Grok models | DJ7: DeepSeek (R- Reasoning models);openAI Reasoning models | DK7: DeepSeek (R- Reasoning models);openAI Reasoning models | DN7: Yes | DO7: A few times per week | DP7: Between 10 and 15 years | DQ7: Less than once per month or monthly | DR7: Long-form articles;Lists of recommendations (tools, frameworks, technologies, etc.);Direct messaging of users;Job board | DS7: 4 | DU7: 9 | DV7: 1 | DW7: 2 | DX7: 7 | DY7: 3 | DZ7: 11 | EA7: 13 | EB7: 15 | ED7: Yes, definitely | EE7: Rarely, almost never | EF7: Yes, I use AI tools daily | EG7: Very favorable | EH7: Somewhat trust | EI7: Bad at handling complex tasks | EJ7: Writing code;Debugging or fixing code;Testing code;Committing and reviewing code | EL7: Learning about a codebase | EM7: Project planning;Deployment and monitoring;Predictive analytics;Learning new concepts or technologies | EN7: Documenting code;Search for answers;Generating content or synthetic data;Creating or maintaining documentation | EO7: AI solutions that are almost right, but not quite;Debugging AI-generated code is more time-consuming | EP7: No. Higher level reasoning including factoring in business constraints, architecture nonsense, management decisions and a general 'feeling' of robustness or performance that I've developer over the years in professional work will probably not be replaced by AI in my lifetime. | EQ7: Yes, I use AI agents at work daily | ER7: Yes, somewhat | ES7: Software engineering;Robotics | ET7: Multi-platform search enablement;Vector databases for AI applications | EU7: AI agents have increased my productivity.;AI agents have accelerated my learning about new technologies or codebases.;AI agents have helped me solve complex problems more effectively.;AI agents have reduced the time spent on specific development tasks.;AI agents have improved collaboration within my team. | EV7: AI agents have improved the quality of my code. | EX7: AI agents have helped me automate repetitive tasks. | EZ7: I am concerned about the accuracy of the information provided by AI agents.;The cost of using certain AI agent platforms is a barrier. | FA7: Integrating AI agents with my existing tools and workflows can be difficult. | FD7: It takes significant time and effort to learn how to use AI agents effectively.;I have concerns about the security and privacy of data when using AI agents.;My company's IT and/or InfoSec teams have strict rules that do not allow me to use AI agent tools or platforms | FE7: Milvus | FG7: Ollama;LangChain | FK7: ChatGPT;Claude Code;GitHub Copilot;Google Gemini;Microsoft Copilot;Perplexity | FL7: codeium, windsurf | FM7: When I want to fully understand something;When I want to compare different solutions | FN7: architectural planning of a big software. That is not going to be replaced for a variety of reasons (some I wrote in the answer before) | FO7: 139218 | FP7: 7
A8: 96 | B8: I am a developer by profession | C8: 45-54 years old | D8: Professional degree (JD, MD, Ph.D, Ed.D, etc.) | E8: Employed | F8: None of the above | G8: 33 | H8: No, I am not new to coding and did not learn new coding techniques or programming languages | J8: No, I didn't spend time learning in the past year | L8: 42 | M8: Developer, AI apps or physical AI | N8: 1,000 to 4,999 employees | O8: Individual contributor | P8: Remote | Q8: No | R8: Work | S8: 11 | T8: 6 | U8: 5 | V8: 4 | W8: 10 | X8: 1 | Y8: 12 | Z8: 7 | AA8: 2 | AB8: 14 | AD8: 14 | AE8: 8 | AF8: 6 | AG8: 7 | AH8: 3 | AI8: 1 | AJ8: 5 | AK8: 13 | AL8: 9 | AM8: 15 | AO8: Manufacturing | AP8: 13 | AQ8: 1 | AR8: 10 | AS8: 11 | AT8: 4 | AU8: 6 | AV8: 5 | AW8: 8 | AX8: 7 | AY8: 14 | AZ8: 9 | BA8: 2 | BB8: 3 | BC8: 15 | BD8: 12 | BF8: No | BG8: I have somewhat considered changing my career and/or the industry I work in | BH8: 5 | BI8: 5 | BJ8: Belgium | BK8: EUR European Euro | BL8: 144000 | BM8: Yes | BN8: C;C++;Lua;Python;SQL | BO8: C++;Python;Rust | BP8: C++;Python | BQ8: VimScript | BR8: VimScript | BS8: Yes | BT8: Oracle;SQLite | BU8: MariaDB;MySQL;PostgreSQL;SQLite | BV8: SQLite | BY8: Yes | BZ8: Amazon Web Services (AWS);Docker;Kubernetes | CE8: No | CK8: No | CV8: Windows;Ubuntu;Windows Subsystem for Linux (WSL) | CW8: Windows;Windows Subsystem for Linux (WSL) | CX8: Azure Devops;Confluence;GitHub;GitLab;Jira;Markdown File;Stack Overflow for Teams | CY8: GitHub;Markdown File | CZ8: GitHub;Markdown File | DC8: Stack Overflow;Stack Exchange;GitHub (public projects, not private repos);LinkedIn | DD8: Stack Overflow;Stack Exchange;GitHub (public projects, not private repos) | DE8: Stack Overflow;Stack Exchange;GitHub (public projects, not private repos) | DH8: No | DN8: Yes | DO8: Multiple times per day | DP8: Between 5 and 10 years | DQ8: Daily or almost daily | DR8: Long-form articles;Lists of recommendations (tools, frameworks, technologies, etc.) | DS8: 13 | DU8: 8 | DV8: 9 | DW8: 11 | DX8: 1 | DY8: 4 | DZ8: 3 | EA8: 7 | EB8: 15 | ED8: Yes, definitely | EE8: I don't use AI or AI-enabled tools | EF8: No, and I don't plan to | EG8: Unfavorable | EH8: Somewhat distrust | EI8: Bad at handling complex tasks | EK8: Learning about a codebase;Project planning;Writing code;Documenting code;Debugging or fixing code;Testing code;Committing and reviewing code;Deployment and monitoring;Creating or maintaining documentation | EL8: Predictive analytics;Search for answers;Generating content or synthetic data;Learning new concepts or technologies | EO8: I don’t use AI tools regularly | EP8: No | EQ8: No, and I don't plan to | ER8: Not at all or minimally | FB8: I have concerns about the security and privacy of data when using AI agents.;My company's IT and/or InfoSec teams have strict rules that do not allow me to use AI agent tools or platforms | FC8: I am concerned about the accuracy of the information provided by AI agents.;Integrating AI agents with my existing tools and workflows can be difficult.;It takes significant time and effort to learn how to use AI agents effectively.;The cost of using certain AI agent platforms is a barrier. | FM8: When I don’t trust AI’s answers;When I want to fully understand something;When I have ethical or security concerns about code | FN8: Analysis of the problem. Creation of logic and algorhytm. | FO8: 167061 | FP8: 8
A9: 120 | B9: I am a developer by profession | C9: 25-34 years old | D9: Master’s degree (M.A., M.S., M.Eng., MBA, etc.) | E9: Employed | F9: None of the above | G9: 4 | H9: Yes, I am not new to coding but am learning new coding techniques or programming language | I9: Technical documentation (is generated for/by the tool or system);AI CodeGen tools or AI-enabled apps | J9: Yes, I learned how to use AI-enabled tools required for my job or to benefit my career | L9: 10 | M9: Data engineer | N9: 1,000 to 4,999 employees | O9: Individual contributor | P9: Hybrid (some in-person, leans heavy to flexibility) | Q9: No | R9: Personal Project | S9: 10 | T9: 12 | U9: 7 | V9: 4 | W9: 3 | X9: 11 | Y9: 8 | Z9: 5 | AA9: 13 | AB9: 14 | AD9: 9 | AE9: 11 | AF9: 4 | AG9: 13 | AH9: 12 | AI9: 6 | AJ9: 1 | AK9: 10 | AL9: 14 | AM9: 15 | AO9: Software Development | AP9: 3 | AQ9: 4 | AR9: 6 | AS9: 2 | AT9: 7 | AU9: 9 | AV9: 8 | AW9: 12 | AX9: 10 | AY9: 1 | AZ9: 14 | BA9: 11 | BB9: 13 | BC9: 15 | BD9: 5 | BF9: No | BG9: I have transitioned into a new career and/or industry voluntarily | BJ9: Spain | BK9: EUR European Euro | BL9: 36000 | BM9: Yes | BN9: HTML/CSS;JavaScript;PHP;Python;SQL;TypeScript | BO9: HTML/CSS;JavaScript;Python;SQL | BP9: HTML/CSS;JavaScript;Python;SQL | BS9: Yes | BT9: MySQL;Oracle;PostgreSQL;Clickhouse | BU9: MySQL;Oracle;PostgreSQL;Clickhouse | BV9: MySQL;Oracle;PostgreSQL;Clickhouse | BY9: Yes | BZ9: Amazon Web Services (AWS);Ansible;Docker | CA9: Docker | CB9: Docker | CE9: Yes | CF9: FastAPI;Flask;React | CG9: FastAPI;Flask | CH9: FastAPI;Flask | CK9: Yes | CL9: Visual Studio Code | CM9: Visual Studio Code | CN9: Visual Studio Code | CV9: Windows;Android | CW9: MacOS | CX9: Confluence;Jira | CY9: Confluence;Jira | CZ9: Confluence;Jira | DA9: Bitbucket | DB9: Bitbucket | DC9: Stack Overflow;LinkedIn;Medium | DD9: Stack Overflow;LinkedIn;Medium | DE9: Stack Overflow;LinkedIn;Medium | DH9: Yes | DI9: openAI GPT (chatbot models) | DJ9: openAI GPT (chatbot models) | DK9: openAI GPT (chatbot models) | DN9: No | DO9: Less than once every 2 - 3 months | DP9: Between 3 and 5 years | DQ9: I have never participated in Q&A on Stack Overflow | EF9: Yes, I use AI tools daily | EG9: Very favorable | EH9: Somewhat trust | EI9: Good, but not great at handling complex tasks | EJ9: Documenting code;Learning new concepts or technologies | EK9: Project planning;Debugging or fixing code;Testing code;Committing and reviewing code;Deployment and monitoring;Generating content or synthetic data;Other (write in): | EL9: Predictive analytics;Creating or maintaining documentation | EN9: Learning about a codebase;Writing code;Search for answers | EO9: AI solutions that are almost right, but not quite;I haven’t encountered any problems | EP9: Yes | EQ9: No, but I plan to | ER9: Yes, to a great extent | FA9: It takes significant time and effort to learn how to use AI agents effectively.;I have concerns about the security and privacy of data when using AI agents. | FC9: I am concerned about the accuracy of the information provided by AI agents. | FD9: Integrating AI agents with my existing tools and workflows can be difficult.;The cost of using certain AI agent platforms is a barrier.;My company's IT and/or InfoSec teams have strict rules that do not allow me to use AI agent tools or platforms | FM9: When I want to learn best practices;When I want to compare different solutions;When I have ethical or security concerns about code;When I need help fixing complex or unfamiliar code | FN9: Soft skills and business knowledge | FO9: 41765 | FP9: 8
A10: 139 | B10: I am a developer by profession | C10: 25-34 years old | D10: Master’s degree (M.A., M.S., M.Eng., MBA, etc.) | E10: Employed | F10: None of the above | G10: 1 | H10: No, I am not new to coding and did not learn new coding techniques or programming languages | J10: No, I didn't spend time learning in the past year | L10: 8 | M10: AI/ML engineer | N10: 5,000 to 9,999 employees | O10: Individual contributor | P10: Your choice (very flexible, you can come in when you want or just as needed) | Q10: No | R10: Work | AO10: Computer Systems Design and Services | BF10: No | BG10: I have neither consider or transitioned into a new career or industry | BJ10: Norway | BK10: NOK Norwegian krone | BL10: 668000 | BM10: Yes | BN10: Bash/Shell (all shells);Go;Java;JavaScript;Python;SQL | BO10: Bash/Shell (all shells);Go;Python;Swift | BP10: Bash/Shell (all shells);Go;Python | BS10: Yes | BT10: Databricks SQL;DuckDB;MongoDB;MySQL | BU10: DuckDB | BV10: DuckDB | BY10: Yes | BZ10: Amazon Web Services (AWS);Docker;Homebrew;Microsoft Azure;Pip;Poetry;Terraform | CA10: Amazon Web Services (AWS);Docker;Homebrew;Kubernetes;Pip;Poetry;Vercel | CB10: Amazon Web Services (AWS);Docker;Homebrew;Pip;Poetry | CE10: No | CK10: Yes | CL10: IntelliJ IDEA;Jupyter Notebook/JupyterLab;PyCharm;Visual Studio Code;Xcode;Zed | CM10: IntelliJ IDEA;PyCharm;Zed | CN10: IntelliJ IDEA;PyCharm;Zed | CQ10: Large Language Model;Amazon Bedrock;RAG | CR10: Polars;Large Language Model;RAG;Microsoft Fabric;Google Gemini | CS10: Large Language Model;RAG | CV10: MacOS;iOS | CW10: MacOS;iOS | CX10: Confluence;GitHub;Google Colab;Google Workspace;Jira;Markdown File;Notion;Obsidian | CY10: GitHub;Google Workspace | CZ10: GitHub;Google Workspace | DC10: Reddit;GitHub (public projects, not private repos);Bluesky;Kaggle;YouTube;Twitch;LinkedIn | DD10: Reddit;GitHub (public projects, not private repos);Bluesky;YouTube;Twitch | DE10: Reddit;GitHub (public projects, not private repos);Bluesky;YouTube;Twitch | DH10: Yes | DI10: Amazon Titan models;Anthropic: Claude Sonnet;Meta Llama (all models);openAI GPT (chatbot models) | DJ10: Gemini (Flash general purpose models);Gemini (Pro Reasoning models);Mistral AI models;openAI Image generating models;openAI Reasoning models | DN10: Yes | DO10: Less than once every 2 - 3 months | DP10: Between 5 and 10 years | DQ10: I have never participated in Q&A on Stack Overflow | ED10: No, not at all | EE10: Less than half of the time | EF10: Yes, I use AI tools daily | EG10: Favorable | EH10: Somewhat trust | EI10: Neither good or bad at handling complex tasks | EJ10: Documenting code;Search for answers;Creating or maintaining documentation;Learning new concepts or technologies | EK10: Learning about a codebase;Committing and reviewing code;Deployment and monitoring;Predictive analytics;Generating content or synthetic data;Other (write in): | EL10: Project planning;Writing code;Debugging or fixing code;Testing code | EO10: AI solutions that are almost right, but not quite;Debugging AI-generated code is more time-consuming;I’ve become less confident in my own problem-solving | EP10: No | EQ10: No, and I don't plan to | ER10: Yes, somewhat | FB10: I am concerned about the accuracy of the information provided by AI agents.;I have concerns about the security and privacy of data when using AI agents. | FC10: Integrating AI agents with my existing tools and workflows can be difficult.;The cost of using certain AI agent platforms is a barrier. | FD10: It takes significant time and effort to learn how to use AI agents effectively.;My company's IT and/or InfoSec teams have strict rules that do not allow me to use AI agent tools or platforms | FM10: When I don’t trust AI’s answers;When I want to fully understand something;When I want to learn best practices;When I have ethical or security concerns about code;When I’m stuck and can’t explain the problem;When I need help fixing complex or unfamiliar code;When I need quick help troubleshooting | FO10: 66017 | FP10: 8
A11: 181 | B11: I am not primarily a developer, but I write code sometimes as part of my work/studies | C11: 25-34 years old | D11: Professional degree (JD, MD, Ph.D, Ed.D, etc.) | E11: Employed | F11: None of the above | G11: 2 | H11: No, I am not new to coding and did not learn new coding techniques or programming languages | J11: No, I didn't spend time learning in the past year | L11: 10 | M11: Applied scientist | N11: 100 to 499 employees | O11: Individual contributor | P11: In-person | Q11: No | R11: Work | S11: 12 | T11: 9 | U11: 8 | V11: 11 | W11: 2 | X11: 10 | Y11: 1 | Z11: 7 | AA11: 4 | AB11: 14 | AD11: 14 | AE11: 3 | AF11: 10 | AG11: 8 | AH11: 7 | AI11: 11 | AJ11: 2 | AK11: 4 | AL11: 9 | AM11: 15 | AO11: Energy | BF11: No | BG11: I have somewhat considered changing my career and/or the industry I work in | BH11: 1 | BI11: 2 | BJ11: Iran, Islamic Republic of... | BK11: USD United States dollar | BL11: 6000 | BM11: Yes | BN11: MATLAB | BO11: Python | BS11: No | BY11: No | CE11: No | CK11: Yes | CL11: Notepad++;Visual Studio;Visual Studio Code | CM11: Visual Studio;Visual Studio Code;Zed | CN11: Visual Studio;Visual Studio Code | CV11: Windows;Android;Windows Subsystem for Linux (WSL) | CW11: Windows | DC11: Stack Overflow;GitHub (public projects, not private repos);Bluesky;X;YouTube;Medium | DD11: Stack Overflow;GitHub (public projects, not private repos);Bluesky;YouTube;Medium | DE11: Stack Overflow;GitHub (public projects, not private repos);Bluesky;YouTube;Medium | DH11: No | DN11: Yes | DO11: A few times per month or weekly | DP11: Between 10 and 15 years | DQ11: Infrequently, less than once per year | DR11: Long-form articles;Lists of recommendations (tools, frameworks, technologies, etc.);Chat (bot/AI) | ED11: Yes, definitely | EE11: Less than half of the time | EF11: Yes, I use AI tools daily | EG11: Very favorable | EH11: Somewhat trust | EI11: Good, but not great at handling complex tasks | EJ11: Writing code;Debugging or fixing code;Committing and reviewing code;Predictive analytics;Learning new concepts or technologies | EL11: Learning about a codebase;Project planning | EM11: Documenting code;Testing code;Deployment and monitoring;Generating content or synthetic data;Creating or maintaining documentation | EN11: Search for answers | EO11: I haven’t encountered any problems | EP11: no | EQ11: No, but I plan to | ER11: Yes, somewhat | FA11: I am concerned about the accuracy of the information provided by AI agents.;It takes significant time and effort to learn how to use AI agents effectively. | FB11: My company's IT and/or InfoSec teams have strict rules that do not allow me to use AI agent tools or platforms | FC11: The cost of using certain AI agent platforms is a barrier.;I have concerns about the security and privacy of data when using AI agents. | FD11: Integrating AI agents with my existing tools and workflows can be difficult. | FM11: I don’t think I’ll need help from people anymore | FN11: mathematical insight | FO11: 6000
A12: 224 | B12: I am not primarily a developer, but I write code sometimes as part of my work/studies | C12: 35-44 years old | D12: Master’s degree (M.A., M.S., M.Eng., MBA, etc.) | E12: Employed | F12: Caring for dependents (children, elderly, etc.) | G12: 20 | H12: Yes, I am not new to coding but am learning new coding techniques or programming language | I12: Other online resources (e.g. standard search, forum, online community);Stack Overflow or Stack Exchange;Technical documentation (is generated for/by the tool or system);Blogs or podcasts;Games or coding challenges | J12: No, I learned something that was not related to AI or AI enablement for my personal curiosity and/or hobbies | L12: 20 | M12: Data or business analyst | N12: 100 to 499 employees | O12: People manager | P12: Hybrid (some remote, leans heavy to in-person) | Q12: Yes, I influenced the purchase of a tool that more than five colleagues use but it is not a substantial addition to the tech stack | R12: Work | S12: 13 | T12: 4 | U12: 6 | V12: 10 | W12: 5 | X12: 1 | Y12: 3 | Z12: 7 | AA12: 2 | AB12: 14 | AD12: 14 | AE12: 5 | AF12: 7 | AG12: 9 | AH12: 3 | AI12: 6 | AJ12: 1 | AK12: 2 | AL12: 13 | AM12: 15 | AO12: Software Development | BF12: No | BG12: I have somewhat considered changing my career and/or the industry I work in | BH12: 5 | BI12: 3 | BJ12: Finland | BK12: EUR European Euro | BL12: 85000 | BM12: Yes | BN12: HTML/CSS;JavaScript;PHP;Python;R;SQL;TypeScript | BO12: Lua;PowerShell;Python;R;SQL;TypeScript | BP12: Python;R;SQL;TypeScript | BS12: Yes | BT12: DuckDB;MariaDB;MySQL;Redis;Snowflake;SQLite;Amazon Redshift | BU12: Databricks SQL;DuckDB;MariaDB;Snowflake;SQLite | BV12: DuckDB;MariaDB;Snowflake;SQLite | BY12: Yes | BZ12: APT;Cloudflare;Composer;Docker;npm;Pip;Vite | CA12: Bun | CD12: ruff, uv | CE12: Yes | CF12: Astro;Laravel;Node.js | CG12: Astro;FastAPI;Laravel | CH12: Astro;Laravel | CI12: Eleventy | CJ12: Eleventy | CK12: Yes | CL12: Nano;Visual Studio Code | CM12: Visual Studio Code | CN12: Visual Studio Code | CO12: DataGrip, micro | CV12: MacOS | CW12: Windows | CX12: Confluence;GitHub;GitLab;Jira;Markdown File;Miro;Obsidian;Wikis | CY12: GitLab;Markdown File;Obsidian;Trello | CZ12: GitLab;Markdown File;Obsidian | DC12: Stack Overflow;Discord;Reddit;GitHub (public projects, not private repos);Bluesky | DF12: lobste.rs | DH12: No | DN12: Yes | DO12: A few times per week | DP12: More than 15 years, or since Stack Overflow started in 2008 | DQ12: Infrequently, less than once per year | DR12: Long-form articles;Coding challenges;Logic games/puzzles | DS12: 1 | DU12: 5 | DV12: 13 | DW12: 10 | DX12: 2 | DY12: 12 | DZ12: 3 | EA12: 14 | EB12: 15 | ED12: Neutral | EE12: I don't use AI or AI-enabled tools | EF12: No, and I don't plan to | EG12: Very unfavorable | EH12: Somewhat distrust | EI12: I don't use AI tools for complex tasks / I don't know | EK12: Learning about a codebase;Project planning;Writing code;Documenting code;Debugging or fixing code;Testing code;Committing and reviewing code;Deployment and monitoring;Predictive analytics;Search for answers;Generating content or synthetic data;Creating or maintaining documentation;Learning new concepts or technologies | EO12: AI solutions that are almost right, but not quite;I don’t use AI tools regularly | EP12: Fuck no. | EQ12: No, and I don't plan to | ER12: No, but my development work has significantly changed due to non-AI factors | EZ12: Integrating AI agents with my existing tools and workflows can be difficult.;It takes significant time and effort to learn how to use AI agents effectively.;The cost of using certain AI agent platforms is a barrier. | FB12: I am concerned about the accuracy of the information provided by AI agents.;My company's IT and/or InfoSec teams have strict rules that do not allow me to use AI agent tools or platforms;Write in the most significant challenge if not listed above: | FC12: I have concerns about the security and privacy of data when using AI agents. | FM12: When I don’t trust AI’s answers;When I want to fully understand something;When I want to learn best practices;When I want to compare different solutions;When I have ethical or security concerns about code;When I’m stuck and can’t explain the problem;When I need help fixing complex or unfamiliar code;When I need quick help troubleshooting | FN12: Everything | FO12: 98612
A13: 237 | B13: I am not primarily a developer, but I write code sometimes as part of my work/studies | C13: 25-34 years old | D13: Bachelor’s degree (B.A., B.S., B.Eng., etc.) | E13: Independent contractor, freelancer, or self-employed | F13: Engaged in paid work (less than 10 hours per week) | G13: 9 | H13: No, I am not new to coding and did not learn new coding techniques or programming languages | J13: Yes, I learned how to use AI-enabled tools for my personal curiosity and/or hobbies | K13: AI CodeGen tools or AI-enabled apps;Other online resources (e.g. standard search, forum, online community);Books / Physical media | L13: 10 | M13: Data scientist | N13: Just me - I am a freelancer, sole proprietor, etc. | O13: Individual contributor | P13: Remote | Q13: Yes, I influenced the purchase of a substantial addition to the tech stack | R13: Work | S13: 4 | T13: 3 | U13: 1 | V13: 6 | W13: 10 | X13: 12 | Y13: 11 | Z13: 9 | AA13: 7 | AB13: 14 | AD13: 6 | AE13: 7 | AF13: 1 | AG13: 11 | AH13: 4 | AI13: 12 | AJ13: 13 | AK13: 8 | AL13: 5 | AM13: 15 | AO13: Software Development | BF13: No | BG13: I have transitioned into a new career and/or industry voluntarily | BH13: 10 | BI13: 10 | BJ13: Switzerland | BK13: CHF Swiss franc | BL13: 50000 | BM13: Yes | BN13: C++;HTML/CSS;JavaScript;Python;Rust | BS13: Yes | BT13: PostgreSQL | BY13: Yes | BZ13: Amazon Web Services (AWS);Cargo;Datadog;Docker;Vite;Webpack | CE13: Yes | CF13: React | CK13: Yes | CL13: IntelliJ IDEA;PyCharm;RustRover;WebStorm | CQ13: Polars;Large Language Model;Amazon Bedrock | CV13: Windows | CW13: Windows;Debian | CX13: Jira | DH13: No | DN13: Yes | DO13: Less than once every 2 - 3 months | DP13: Between 5 and 10 years | DQ13: Less than once every 2 - 3 months | DR13: Chat (bot/AI) | DS13: 14 | DU13: 2 | DV13: 7 | DW13: 4 | DX13: 6 | DY13: 9 | DZ13: 10 | EA13: 5 | EB13: 15 | EC13: It's a crazy amount of time to rank 15 answers, guys | ED13: No, not really | EE13: Rarely, almost never | EF13: Yes, I use AI tools daily | EG13: Very favorable | EH13: Highly trust | EI13: Very well at handling complex tasks | EL13: Deployment and monitoring;Generating content or synthetic data | EN13: Learning about a codebase;Project planning;Writing code;Documenting code;Debugging or fixing code;Testing code;Committing and reviewing code;Predictive analytics;Search for answers;Creating or maintaining documentation;Learning new concepts or technologies | EO13: AI solutions that are almost right, but not quite;I haven’t encountered any problems | EP13: Yes, of course | EQ13: No, but I plan to | ER13: Yes, to a great extent | EZ13: I have concerns about the security and privacy of data when using AI agents. | FC13: I am concerned about the accuracy of the information provided by AI agents. | FD13: Integrating AI agents with my existing tools and workflows can be difficult.;It takes significant time and effort to learn how to use AI agents effectively.;The cost of using certain AI agent platforms is a barrier.;My company's IT and/or InfoSec teams have strict rules that do not allow me to use AI agent tools or platforms;Write in the most significant challenge if not listed above: | FM13: When I don’t trust AI’s answers;When I want to fully understand something;When I want to learn best practices;When I want to compare different solutions;When I have ethical or security concerns about code | FN13: Being capable of writing code and understanding it deeply. Not only the syntax, but also how to parallelize code,... I don't think the skills/requirements from employees will change | FO13: 61996
A14: 243 | B14: I am a developer by profession | C14: 25-34 years old | D14: Master’s degree (M.A., M.S., M.Eng., MBA, etc.) | E14: Employed | F14: Engaged in paid work (20-29 hours per week) | G14: 6 | H14: Yes, I am not new to coding but am learning new coding techniques or programming language | I14: Other online resources (e.g. standard search, forum, online community);AI CodeGen tools or AI-enabled apps | J14: Yes, I learned how to use AI-enabled tools for my personal curiosity and/or hobbies | K14: Other online resources (e.g. standard search, forum, online community);Blogs or podcasts | L14: 10 | M14: Data engineer | N14: 20 to 99 employees | O14: Individual contributor | P14: Your choice (very flexible, you can come in when you want or just as needed) | Q14: No | R14: Work | S14: 13 | T14: 3 | U14: 2 | V14: 1 | W14: 4 | X14: 8 | Y14: 12 | Z14: 6 | AA14: 7 | AB14: 11 | AD14: 13 | AE14: 3 | AF14: 5 | AG14: 7 | AH14: 6 | AI14: 1 | AJ14: 8 | AK14: 9 | AL14: 14 | AM14: 11 | AO14: Software Development | BF14: No | BG14: I have neither consider or transitioned into a new career or industry | BH14: 5 | BI14: 5 | BJ14: United Kingdom of Great Britain and Northern Ireland | BK14: GBP Pound sterling | BL14: 67000 | BM14: Yes | BN14: Bash/Shell (all shells);C#;HTML/CSS;Java;JavaScript;PowerShell;Python;Rust;Scala;SQL | BO14: C#;Go;HTML/CSS;PowerShell;Python;SQL | BP14: C#;HTML/CSS;PowerShell;Python;SQL | BS14: Yes | BT14: DuckDB;Dynamodb;Microsoft SQL Server;MongoDB;MySQL;PostgreSQL;SQLite | BU14: DuckDB;PostgreSQL;SQLite | BV14: DuckDB;PostgreSQL;SQLite | BY14: Yes | BZ14: Amazon Web Services (AWS);Digital Ocean;Docker;Google Cloud;npm;Pip;Terraform;Yarn | CA14: Amazon Web Services (AWS);Pip;Terraform;Yarn | CB14: Amazon Web Services (AWS);Pip;Terraform;Yarn | CE14: Yes | CF14: Django;Express;Flask;Next.js;Node.js;React | CG14: Django;Express;Flask | CH14: Django;Express;Flask | CK14: Yes | CL14: Notepad++;Visual Studio Code | CM14: Notepad++;Visual Studio Code | CN14: Notepad++;Visual Studio Code | CQ14: Polars;Large Language Model;Amazon Bedrock;RAG;Google Gemini | CR14: Polars;Large Language Model;Amazon Bedrock;RAG;Google Gemini | CS14: Polars;Large Language Model;Amazon Bedrock;RAG;Google Gemini | CV14: Windows;Ubuntu;Android;Debian | CW14: MacOS;Windows Subsystem for Linux (WSL);iOS | CX14: Confluence;GitHub;Google Colab;Jira;Obsidian;Wikis | CY14: GitHub;Obsidian;Wikis | CZ14: GitHub;Obsidian;Wikis | DC14: Stack Overflow;Stack Exchange;Discord;Reddit;Hacker News;GitHub (public projects, not private repos);Slack (public channels, not work);X;YouTube;Twitch;LinkedIn;Substack;Medium | DD14: Hacker News;GitHub (public projects, not private repos);YouTube;Substack | DE14: Hacker News;GitHub (public projects, not private repos);YouTube;Substack | DH14: Yes | DI14: DeepSeek (V- General purpose models);Meta Llama (all models);Mistral AI models;openAI GPT (chatbot models);openAI Image generating models;openAI Reasoning models | DJ14: Mistral AI models;openAI GPT (chatbot models);openAI Image generating models;openAI Reasoning models | DK14: Mistral AI models;openAI GPT (chatbot models);openAI Image generating models;openAI Reasoning models | DN14: No | DO14: A few times per month or weekly | DP14: Between 5 and 10 years | DQ14: I have never participated in Q&A on Stack Overflow | ED14: No, not at all | EE14: Less than half of the time | EF14: Yes, I use AI tools daily | EG14: Very favorable | EH14: Highly distrust | EI14: Bad at handling complex tasks | EJ14: Search for answers;Generating content or synthetic data;Creating or maintaining documentation | EK14: Learning about a codebase;Testing code;Committing and reviewing code;Deployment and monitoring;Predictive analytics | EL14: Project planning;Debugging or fixing code | EM14: Writing code;Documenting code | EN14: Learning new concepts or technologies | EO14: AI solutions that are almost right, but not quite;Debugging AI-generated code is more time-consuming | EP14: Nope | EQ14: No, and I don't plan to | ER14: Yes, somewhat | EZ14: My company's IT and/or InfoSec teams have strict rules that do not allow me to use AI agent tools or platforms | FA14: Integrating AI agents with my existing tools and workflows can be difficult. | FB14: I am concerned about the accuracy of the information provided by AI agents.;The cost of using certain AI agent platforms is a barrier.;I have concerns about the security and privacy of data when using AI agents. | FD14: It takes significant time and effort to learn how to use AI agents effectively. | FM14: When I don’t trust AI’s answers;When I want to fully understand something;When I want to learn best practices;When I want to compare different solutions;When I have ethical or security concerns about code;When I’m stuck and can’t explain the problem;When I need help fixing complex or unfamiliar code | FN14: The main ones that we still use now and have done for the past several decades. | FO14: 91215
